<?xml version="1.0" ?>
<!-- =================================================================================== -->
<!-- |    This document was autogenerated by xacro from robot.urdf.xacro               | -->
<!-- |    EDITING THIS FILE BY HAND IS NOT RECOMMENDED                                 | -->
<!-- =================================================================================== -->
<robot name="robot">
  <gazebo>
    <!--plugin
            filename="gz-sim-pose-publisher-system"
            name="gz::sim::systems::PosePublisher">
            <publish_link_pose>true</publish_link_pose>
            <use_pose_vector_msg>true</use_pose_vector_msg>
            <static_publisher>true</static_publisher>
            <static_update_frequency>1</static_update_frequency>
        </plugin-->
    <!--plugin
            filename="gz-sim-odometry-publisher-system"
            name="gz::sim::systems::OdometryPublisher">
            <odom_frame>robot/odom</odom_frame>
            <robot_base_frame>robot/base_link</robot_base_frame>
            <odom_publish_frequency>50</odom_publish_frequency>
        </plugin-->
    <plugin filename="gz-sim-joint-state-publisher-system" name="gz::sim::systems::JointStatePublisher">
        </plugin>
    <plugin filename="gz-sim-diff-drive-system" name="gz::sim::systems::DiffDrive">
      <left_joint>left_wheel_joint</left_joint>
      <right_joint>right_wheel_joint</right_joint>
      <child_frame_id>robot/base_link</child_frame_id>
      <wheel_separation>0.291</wheel_separation>
      <wheel_radius>0.033</wheel_radius>
      <odom_publish_frequency>10</odom_publish_frequency>
    </plugin>
  </gazebo>
  <!--xacro:include filename="$(find robot_description)/urdf/lidar.urdf.xacro" /-->
  <!--xacro:include filename="$(find robot_description)/urdf/depth.urdf.xacro" /-->
  <material name="white">
    <color rgba="1 1 1 1"/>
  </material>
  <material name="orange">
    <color rgba="1 0.3 0.1 1"/>
  </material>
  <material name="blue">
    <color rgba="0.2 0.2 1 1"/>
  </material>
  <material name="black">
    <color rgba="0 0 0 1"/>
  </material>
  <material name="red">
    <color rgba="1 0 0 1"/>
  </material>
  <link name="base_link">
    </link>
  <link name="base_footprint">
    </link>
  <joint name="base_footprint_joint" type="fixed">
    <parent link="base_link"/>
    <child link="base_footprint"/>
    <origin rpy="0 0 0" xyz="0 0 -0.138"/>
  </joint>

    -- Нижняя платформа

  <joint name="chassis_joint" type="fixed">
    <parent link="base_link"/>
    <child link="chassis"/>
    <origin xyz="-0.38 0 0.01"/>
  </joint>
  <link name="chassis">
    <inertial>
      <origin rpy="0 0 0" xyz="0.45 0 0.225"/>
      <mass value="1.0"/>
      <inertia ixx="0.03375" ixy="0.0" ixz="0.0" iyy="0.084375" iyz="0.0" izz="0.084375"/>
    </inertial>
    <visual>
      <origin xyz="0.45 0 0.225"/>
      <geometry>
        <box size="0.9 0.45 0.45"/>
      </geometry>
      <material name="orange"/>
    </visual>
    <collision>
      <origin xyz="0.45 0 0.225"/>
      <geometry>
        <box size="0.9 0.45 0.45"/>
      </geometry>
    </collision>
  </link>
  <gazebo reference="chassis">
    <material>Gazebo/Orange</material>
  </gazebo>


     -- ВВерхняя платформа

  <joint name="chassis_up_joint" type="fixed">
    <parent link="base_link"/>
    <child link="chassis_up"/>
    <origin xyz="-0.65 0 0.32"/>
  </joint>
  <link name="chassis_up">
    <inertial>
      <origin rpy="0 0 0" xyz="0.45 0 0.225"/>
      <mass value="0.0000000001"/>
      <inertia ixx="3.3750000000000005e-12" ixy="0.0" ixz="0.0" iyy="8.437500000000002e-12" iyz="0.0" izz="8.437500000000002e-12"/>
    </inertial>
    <visual>
      <origin xyz="0.45 0 0.225"/>
      <geometry>
        <box size="0.35 0.45 0.45"/>
      </geometry>
      <material name="orange"/>
    </visual>
    <collision>
      <origin xyz="0.45 0 0.225"/>
      <geometry>
        <box size="0.2 0.2 0.2"/>
      </geometry>
    </collision>
  </link>
  <gazebo reference="chassis_up">
    <material>Gazebo/Orange</material>
  </gazebo>
  --дуло


    <joint name="chassis_up_joint_d" type="fixed">
    <parent link="base_link"/>
    <child link="chassis_up_d"/>
    <origin xyz="-0.4 0 0.4"/>
  </joint>
  <link name="chassis_up_d">
    <inertial>
      <origin rpy="0 0 0" xyz="0.1 0 0.1"/>
      <mass value="0.0000000001"/>
      <inertia ixx="3.3750000000000005e-12" ixy="0.0" ixz="0.0" iyy="8.437500000000002e-12" iyz="0.0" izz="8.437500000000002e-12"/>
    </inertial>
    <visual>
      <origin xyz="0.45 0 0.225"/>
      <geometry>
        <box size="0.6 0.1 0.1"/>
      </geometry>
      <material name="orange"/>
    </visual>
    <collision>
      <origin xyz="0.45 0 0.225"/>
      <geometry>
        <box size="0.2 0.2 0.2"/>
      </geometry>
    </collision>
  </link>
  <gazebo reference="chassis_up_d">
    <material>Gazebo/Orange</material>
  </gazebo>
  <joint name="left_wheel_joint" type="continuous">
    <parent link="base_link"/>
    <child link="left_wheel"/>
    <origin rpy="-1.5707963267948966 0 0" xyz="0.38 0.24 0.07"/>
    <axis xyz="0 0 1"/>
  </joint>
  <link name="left_wheel">
    <visual>
      <geometry>
        <cylinder length="0.026" radius="0.11"/>
      </geometry>
      <material name="blue"/>
    </visual>
    <collision>
      <geometry>
        <sphere radius="0.11"/>
      </geometry>
    </collision>
    <inertial>
      <origin rpy="0 0 0" xyz="0 0 0"/>
      <mass value="0.05"/>
      <inertia ixx="0.00015406666666666668" ixy="0.0" ixz="0.0" iyy="0.00015406666666666668" iyz="0.0" izz="0.00030250000000000003"/>
    </inertial>
  </link>
  <gazebo reference="left_wheel">
    <material>Gazebo/Blue</material>
  </gazebo>
  <joint name="right_wheel_joint" type="continuous">
    <parent link="base_link"/>
    <child link="right_wheel"/>
    <origin rpy="1.5707963267948966 0 0" xyz="0.38 -0.24 0.07"/>
    <axis xyz="0 0 -1"/>
  </joint>
  <link name="right_wheel">
    <visual>
      <geometry>
        <cylinder length="0.026" radius="0.11"/>
      </geometry>
      <material name="blue"/>
    </visual>
    <collision>
      <geometry>
        <sphere radius="0.11"/>
      </geometry>
    </collision>
    <inertial>
      <origin rpy="0 0 0" xyz="0 0 0"/>
      <mass value="0.05"/>
      <inertia ixx="0.00015406666666666668" ixy="0.0" ixz="0.0" iyy="0.00015406666666666668" iyz="0.0" izz="0.00030250000000000003"/>
    </inertial>
  </link>
  <gazebo reference="right_wheel">
    <material>Gazebo/Blue</material>
  </gazebo>
  <joint name="caster_wheel_joint" type="fixed">
    <parent link="chassis"/>
    <child link="caster_wheel"/>
    <origin xyz="0.075 0 -0.02"/>
  </joint>
  <link name="caster_wheel">
    <visual>
      <geometry>
        <sphere radius="0.04"/>
      </geometry>
      <material name="white"/>
    </visual>
    <collision>
      <geometry>
        <sphere radius="0.04"/>
      </geometry>
    </collision>
    <inertial>
      <origin rpy="0 0 0" xyz="0 0 0"/>
      <mass value="0.05"/>
      <inertia ixx="3.2000000000000005e-05" ixy="0.0" ixz="0.0" iyy="3.2000000000000005e-05" iyz="0.0" izz="3.2000000000000005e-05"/>
    </inertial>
  </link>
  <gazebo reference="caster_wheel">
    <material>Gazebo/White</material>
    <mu1 value="0.001"/>
    <mu2 value="0.001"/>
  </gazebo>
</robot>
